Workbook
Name Strength: 'Main Sheet'!$G$9
Name BaseAttack: 'Main Sheet'!$AM$6
Name tSizeChange: 'Main Sheet'!$AK$74
Name Charisma: 'Main Sheet'!$G$14
Name tSkill: 'Main Sheet'!$AQ$74
Name Level: 'Main Sheet'!$AQ$6
Name Intelligence: 'Main Sheet'!$G$12
Name Size: 'Main Sheet'!$D$5
Name tRangedDamage: 'Main Sheet'!$AE$74
Name tOHDamage: 'Main Sheet'!$AA$74
Name tRangedAttack: 'Main Sheet'!$AD$74
Name tMeleeDamage: 'Main Sheet'!$Z$74
Name t2HDamage: 'Main Sheet'!$AB$74
Name Tier: 'Main Sheet'!$AQ$5
Name SizeTable: 'Formula References'!$A$138:$G$146
Name Wisdom: 'Main Sheet'!$G$13
Name tMeleeAttack: 'Main Sheet'!$Y$74
Name Dexterity: 'Main Sheet'!$G$10
Name Constitution: 'Main Sheet'!$G$11

Sheet Welcome Page
M1: This sheet is free to use, but a Paypal link is listed below. Maintaining this old gal is a labor of love that requires many sleepless hours, so if you feel that this project is worthy, please consider donating a small amount. :) I want to thank Paizo for creating an awesome game, my friends and fellow gamers for playing it with me, and /r/pathfinder_rpg for being an awesome community.
B2: Welcome to the Pathfinder AutoSheet v6!
B3: To use this character sheet, you must first copy it to your own Google Drive. You will then have full Edit access to that version. | M3: Email: | N3: autopathfindersheet@gmail.com | P3: Reddit: | Q3: /u/darthmarth28
M4: Paypal Link: | N4: https://www.paypal.com/cgi-bin/webscr?cmd=_donations&business=SQ5H3R27U4L68&lc=US&item_name=Automated%20Pathfinder%20Character%20Sheet&currency_code=USD&bn=PP%2dDonationsBF%3abtn_donate_SM%2egif%3aNonHosted
B5: The most up to date Version is: | D5: White cells are not referenced by anything - write notes here! | H5: =HYPERLINK("https://docs.google.com/spreadsheets/d/1ZCnFreS_IkbePoHv80NFlIB8QQgTygF6BXTC43NI7s8/copy","CLICK HERE TO MAKE A COPY") -> CLICK HERE TO MAKE A COPY | N5: Alt. Rules:
C6: =IFERROR(__xludf.DUMMYFUNCTION("IMPORTRANGE(""1ZCnFreS_IkbePoHv80NFlIB8QQgTygF6BXTC43NI7s8"",""Welcome Page!C7"")"),"v6.2.1") -> v6.2.1 | D6: Yellow cells are referenced by formulas and refer to pluses | N6: Unchained Skills | P6: Background Skills
B7: This sheet is: | C7: v6.2.1 | D7: Red cells are referenced by formulas and refer to minuses | N7: Wound Thresholds | P7: INACTIVE
B8: =IF(C7=C6,"This Sheet is up to Date!",hyperlink("https://docs.google.com/spreadsheets/d/1ZCnFreS_IkbePoHv80NFlIB8QQgTygF6BXTC43NI7s8/edit#gid=1828856411","Click here for the Changelog!")) -> This Sheet is up to Date! | D8: Grey cells contain formulas, and should not be edited! | N8: Minimum 4+INT skill ranks | P8: INACTIVE
K9: Don't worry, its safe. Click "Advanced" to proceed. Ctrl+z works to undo the effects of the script
B10: Mini-FAQ (Permissions and Compatibility): | H10: Other Pathfinder Resources by me: | L10: "File" -> "Make a Copy" | N10: Protips:
B11: > No, I will not grant you access to this sheet. This is the Master. You may not build your PC on it. My Gmail automatically filters requests. | J11: Massive, comprehensive, and automatically updating. Copy/Paste the address of your copied sheet to link this seperate GooglyDoc to your PC. (See ImportRange permissions protip to the right if you're having difficulties - sharing permissions are important!) | N11: This sheet is meant to be viewed without gridlines. It will look super ugly if you have them enabled. To toggle gridlines, go to "View", then uncheck "Gridlines"
H12: =hyperlink("https://docs.google.com/spreadsheets/d/10b3sYEcrGAybAWJEVJzm7jdDWlaxRXnkDF1IRDOVYis/edit#gid=1919188920","AutoSpellcasting Sheet") -> AutoSpellcasting Sheet
B13: I followed the link to make a copy, but it still isn't letting me Edit. > If the provided link doesn't work, try making a manual copy to your personal Drive by going to "File" -> "Make a Copy". If that's still giving you grief, double check that it is "Copy of Pathfinder Autosheet" and that it is from your Google Drive - the most common error I've seen is being signed into alternate work or school Google accounts. | N13: Hover over this cell to learn how to Insert Notes Notes are a HUGE asset to minutia tracking - very important for when the GM asks how in the hell you have a +59 to Stealth checks without Invisibility.
J14: Are you a pack rat? an OCD neat-freak? Does your GM force your party to actually track encumbrance? This Equipment page has you covered. Features multiple sections to sort your gear and automatically calculates carry capacity for you, your magical bags, AND a pack animal!
H15: =hyperlink("https://docs.google.com/spreadsheets/d/1rWBgTIy3lCH1-l5D29KfuyMGgP0MWEyleF5Fxeiddyg/edit#gid=641126097","Equipment Tracker") -> Equipment Tracker
N16: Named Ranges: many important values can now be used by directly typing their names into formulas. For a complete list, see "Data" --> "Named Ranges".
B17: I can't find feature X that was in Autosheet v5, what gives? > Some of v6's functionality has been split over multiple spreadsheets. Cohorts and Animal Companions should get their own sheet, the old-school Spell Sheet is a standalone now (see right), and Encumbrance-tracking madmen can find that feature in the Equipment Tracker (ditto). While it IS possible to reintigrate these support sheets, doing so is difficult and may make the sheet laggy and less responsive. I suggest pasting a hyperlink to your support sheets into the Main Sheet's note section. | H17: =Hyperlink("https://docs.google.com/spreadsheets/d/1jRs4ilch6pSaXnAAnap_8lSWxMsKiPKuh864yXR6e1Y/edit?usp=sharing","Party Treasure, XP, and GM Reference") -> Party Treasure, XP, and GM Reference | J17: Input Treasure and XP into this chart to track your progress as you adventure. Easily divide your rewards fairly. Also has calculations for debts, loans, and of course XP tracking. Every party should have 1 shared copy of this sheet. Also contains an automated GM Reference Screen
N18: Printing this character sheet: I recommend 69% zoom, Narrow Margins, and Portrait orientation. This cuts the less-important right-hand edge of the sheet off while retaining all of the critical information. I also recommend: 1. Replacing the Quick Toggle section with large resource-tracking boxes 2. Add 13 rows above Spellcasting to place that section entirely on the second page instead of being cut in half by the page break (or delete/hide rows 59-68 if you're a tertiary caster). Maybe move the Resources, Magic Items, and Notes sections that would otherwise be deleted over to this new space. 3. Edit the HP box to =" / " & $AK$6 4. Print in Black and White, obviously
J20: You probably don't need this, but my players do. Have a look if you'd like, though! -- Feat Tax reduction -- Class Balancing (buffs/bans) -- New/Modified Feats (more buffs/bans) -- Marksman Weapons (new firearm/crossbow rules)
H21: =Hyperlink("https://drive.google.com/open?id=1vhwAw2KgXBohwIwTGGuga5SaddjMf4ul0P5CXWag6HU","My Personal Houserule Doc") -> My Personal Houserule Doc
B23: Can I do a thing with this sheet? | J23: Like Pathfinder? Like Sci-Fi? You're probably already a fan of Starfinder. The Starfinder Autosheet contains all the goodies and tricks of the Pathfinder Autosheet, combined with a sweet sci-fi color scheme.
B24: > You may use or modify this sheet for any non-commercial purpose. You may link to this sheet from other websites, but you may not rehost this sheet as your own work. | H24: =Hyperlink("https://drive.google.com/open?id=1Fv86mdaBe2QPKiUMUWea1Mhnv9PRIX4tWIYz6cgQkzI","Starfinder Autosheet") -> Starfinder Autosheet
H25: (still incomplete / in Beta)
B26: My internet is terrible. Can I use this offline? | J26: The previous-gen Autosheet, if for some reason you decide this one is ugly and everything is terrible about it... or if it breaks for some strange reason and I can't figure out why for a while. | N26: ImportRange updates only when something else on the sheet is changed, NOT a timer, so if you're trying to keep something like the "Party Treasure, XP, and GM Reference" sheet synced, all you need to do is type a quick string of gibberish in the margins, hit Enter, and re-delete it.
B27: > To use the autosheet offline, try downloading the offline Googlesheets app. The AutoSpellcasting Sheet ABSOLUTELY will not work, but everything else should. Unfortunately, this sheet isn't compatible with Microsoft Excel. Many of its important formulas rely on GoogleSheet-only commands. | H27: =HYPERLINK("https://drive.google.com/open?id=1V6l7A0kaPkPUjNlwFEqziMnE5NWnCELZ42yW4ePbexE","Pathfinder Autosheet v5") -> Pathfinder Autosheet v5
N29: ImportRange permissions may cause an error for the AutoSpellcasting, Equipment , or Party Treasure support sheets. In order to work, these sheets need permission to access the main sheet they pull values from just like a human would. You can solve this problem by setting everything's Sharing Settings to "Viewable by Everyone with the Hyperlink".
N33: Building an Undead Character? You'll want to set your Constitution score equal to your Charisma score (overwrite F11 with "=F14"), with that done, you can hide the Constitution row either by filling it Black or changing the text color to the same parchment-esque yellow as the background.
B34: DO NOT DELETE THIS TAB! When those grey cells in the top-right go missing, lots of things break. | K34: (actually just Skills, but you get the picture)
B35: Feel free to right click the red "Welcome Page" tab below and select "Hide Sheet" though. You can find it again by going to the top bar menu, View->Hidden Sheets
N37: Massive Errors in the Skills Section probably originate from either trying to customize the skill list or messing up the formatting. The cell which is causing you grief is AE9 "Acrobatics", which is importing the entire 34-row list of skills from the bottom of the Formula References tab. You can either Copy AE9:AE45 and Right-Click -> "Paste Special" -> "Paste Values Only..." to break the OFFSET formula, or you can edit the Formula References tab to change things around.

Sheet Main Sheet
AD1: Category Filter | AG1: Class | AK1: HD | AL1: Skills | AM1: BAB | AN1: Fort | AO1: Reflex | AP1: Will | AQ1: Level
B2: Charlie | J2: Neutral | N2: Runecarved Human | V2: Medium | AA2: Favored Class Bonuses | AD2: Akashic Classes | AE2: Rajah | AK2: =if($AQ2>0, int(vlookup($AE2, 'Class Charts'!$B:$N,2,False)),) -> 6 | AL2: =if('Welcome Page'!$P$6="Consolidated", if($AQ2>0, MAX(1,int((vlookup($AE2, 'Class Charts'!$B:$N,7,False)+Intelligence)/2)), ), if($AQ2>0, MAX(1,if('Welcome Page'!$P$8="ACTIVE", Max(4,vlookup($AE2, 'Class Charts'!$B:$N,7,False))+Intelligence, vlookup($AE2, 'Class Charts'!$B:$N,7,False)+Intelligence)), ) ) -> 14 | AM2: =if($AQ2>0, int(vlookup($AE2, 'Class Charts'!$B:$N,3,False)*$AQ2),) -> 1 | AN2: =if($AQ2>0, if(vlookup($AE2,'Class Charts'!$B:$N,4,false)="Good",2+INT($AQ2/2), if(vlookup($AE2,'Class Charts'!$B:$N,4,false)="Poor", int($AQ2/3), if(vlookup($AE2,'Class Charts'!$B:$N,4,false)="Prestige Good",INT(($AQ2+1)/2), if(vlookup($AE2,'Class Charts'!$B:$N,4,false)="Prestige Poor",INT(($AQ2+1)/3),)))),) -> 3 | AO2: =if($AQ2>0, if(vlookup($AE2,'Class Charts'!$B:$N,5,false)="Good",2+INT($AQ2/2), if(vlookup($AE2,'Class Charts'!$B:$N,5,false)="Poor", int($AQ2/3), if(vlookup($AE2,'Class Charts'!$B:$N,5,false)="Prestige Good",INT(($AQ2+1)/2), if(vlookup($AE2,'Class Charts'!$B:$N,5,false)="Prestige Poor",INT(($AQ2+1)/3),)))),) -> 1 | AP2: =if($AQ2>0, if(vlookup($AE2,'Class Charts'!$B:$N,6,false)="Good",2+INT($AQ2/2), if(vlookup($AE2,'Class Charts'!$B:$N,6,false)="Poor", int($AQ2/3), if(vlookup($AE2,'Class Charts'!$B:$N,6,false)="Prestige Good",INT(($AQ2+1)/2), if(vlookup($AE2,'Class Charts'!$B:$N,6,false)="Prestige Poor",INT(($AQ2+1)/3),)))),) -> 3 | AQ2: 3
B3: Character Name | J3: Alignment | N3: Race | R3: Deity | V3: XP Growth Rate | AA3: Bonus HP | AD3: 3PP-Martial | AE3: Stalker | AK3: =if($AQ3>0, int(vlookup($AE3, 'Class Charts'!$B:$N,2,False)),) -> 8 | AL3: =if('Welcome Page'!$P$6="Consolidated", if($AQ3>0, MAX(1,int((vlookup($AE3, 'Class Charts'!$B:$N,7,False)+Intelligence)/2)), ), if($AQ3>0, MAX(1,if('Welcome Page'!$P$8="ACTIVE", Max(4,vlookup($AE3, 'Class Charts'!$B:$N,7,False))+Intelligence, vlookup($AE3, 'Class Charts'!$B:$N,7,False)+Intelligence)), ) ) -> 14 | AM3: =if($AQ3>0, int(vlookup($AE3, 'Class Charts'!$B:$N,3,False)*$AQ3),) -> 2 | AN3: =if($AQ3>0, if(vlookup($AE3,'Class Charts'!$B:$N,4,false)="Good",2+INT($AQ3/2), if(vlookup($AE3,'Class Charts'!$B:$N,4,false)="Poor", int($AQ3/3), if(vlookup($AE3,'Class Charts'!$B:$N,4,false)="Prestige Good",INT(($AQ3+1)/2), if(vlookup($AE3,'Class Charts'!$B:$N,4,false)="Prestige Poor",INT(($AQ3+1)/3),)))),) -> 1 | AO3: =if($AQ3>0, if(vlookup($AE3,'Class Charts'!$B:$N,5,false)="Good",2+INT($AQ3/2), if(vlookup($AE3,'Class Charts'!$B:$N,5,false)="Poor", int($AQ3/3), if(vlookup($AE3,'Class Charts'!$B:$N,5,false)="Prestige Good",INT(($AQ3+1)/2), if(vlookup($AE3,'Class Charts'!$B:$N,5,false)="Prestige Poor",INT(($AQ3+1)/3),)))),) -> 1 | AP3: =if($AQ3>0, if(vlookup($AE3,'Class Charts'!$B:$N,6,false)="Good",2+INT($AQ3/2), if(vlookup($AE3,'Class Charts'!$B:$N,6,false)="Poor", int($AQ3/3), if(vlookup($AE3,'Class Charts'!$B:$N,6,false)="Prestige Good",INT(($AQ3+1)/2), if(vlookup($AE3,'Class Charts'!$B:$N,6,false)="Prestige Poor",INT(($AQ3+1)/3),)))),) -> 3 | AQ3: 3
W4: =iferror((HLOOKUP(V2,'Formula References'!B114:D134,AQ6+2,false)-V5)/1000&"k XP to next level","") -> 9k XP to next level | AA4: Bonus Skills | AD4: Monstrous | AK4: =if($AQ4>0, int(vlookup($AE4, 'Class Charts'!$B:$N,2,False)),) | AL4: =if('Welcome Page'!$P$6="Consolidated", if($AQ4>0, MAX(1,int((vlookup($AE4, 'Class Charts'!$B:$N,7,False)+Intelligence)/2)), ), if($AQ4>0, MAX(1,if('Welcome Page'!$P$8="ACTIVE", Max(4,vlookup($AE4, 'Class Charts'!$B:$N,7,False))+Intelligence, vlookup($AE4, 'Class Charts'!$B:$N,7,False)+Intelligence)), ) ) | AM4: =if($AQ4>0, int(vlookup($AE4, 'Class Charts'!$B:$N,3,False)*$AQ4),) | AN4: =if($AQ4>0, if(vlookup($AE4,'Class Charts'!$B:$N,4,false)="Good",2+INT($AQ4/2), if(vlookup($AE4,'Class Charts'!$B:$N,4,false)="Poor", int($AQ4/3), if(vlookup($AE4,'Class Charts'!$B:$N,4,false)="Prestige Good",INT(($AQ4+1)/2), if(vlookup($AE4,'Class Charts'!$B:$N,4,false)="Prestige Poor",INT(($AQ4+1)/3),)))),) | AO4: =if($AQ4>0, if(vlookup($AE4,'Class Charts'!$B:$N,5,false)="Good",2+INT($AQ4/2), if(vlookup($AE4,'Class Charts'!$B:$N,5,false)="Poor", int($AQ4/3), if(vlookup($AE4,'Class Charts'!$B:$N,5,false)="Prestige Good",INT(($AQ4+1)/2), if(vlookup($AE4,'Class Charts'!$B:$N,5,false)="Prestige Poor",INT(($AQ4+1)/3),)))),) | AP4: =if($AQ4>0, if(vlookup($AE4,'Class Charts'!$B:$N,6,false)="Good",2+INT($AQ4/2), if(vlookup($AE4,'Class Charts'!$B:$N,6,false)="Poor", int($AQ4/3), if(vlookup($AE4,'Class Charts'!$B:$N,6,false)="Prestige Good",INT(($AQ4+1)/2), if(vlookup($AE4,'Class Charts'!$B:$N,6,false)="Prestige Poor",INT(($AQ4+1)/3),)))),)
B5: Medium | D5: =iferror(OFFSET('Formula References'!$A$137,MIN(MAX(1,MATCH($B$5,'Formula References'!$B$138:$B$146,0)+AK74),9),0), OFFSET('Formula References'!$A$137,MIN(MAX(1,MATCH("Medium",'Formula References'!$B$138:$B$146,0)+AK74),9),0) ) -> M | F5: Adult | AA5: Other Bonus
B6: Base/Current Size | F6: Age Category | V6: Experience Points | Z6: Gestalt | AC6: TRUE | AD6: Totals | AK6: =if(AC6=FALSE, HLOOKUP($V$8,'Formula References'!H3:M4,2,false)+Z3,MAX(HLOOKUP($V$8,'Formula References'!H3:M8,3,false)+Z3,HLOOKUP($V$8,'Formula References'!H3:M8,4,false)+Z3,HLOOKUP($V$8,'Formula References'!H3:M8,5,false)+Z3)) -> 36 | AL6: {=if(AC6=FALSE, SUM(AL2:AL4*AQ2:AQ4,AS2:AS4)+Z4,MAX(AL2:AL4*AQ2:AQ4)+Z4)} -> 42 | AM6: =if(AC6=FALSE,SUM(AM2:AM5),MAX(AM2:AM5)) -> 2 | AN6: =if(AC6=FALSE,SUM(AN2:AN5),MAX(AN2:AN5)) -> 3 | AO6: =if(AC6=FALSE,SUM(AO2:AO5),MAX(AO2:AO5)) -> 1 | AP6: =if(AC6=FALSE,SUM(AP2:AP5), MAX(AP2:AP5)) -> 3 | AQ6: =if(AC6=TRUE,Max(AQ2:AQ4), SUM(AQ2:AQ4)) -> 3
AK7: HP | AL7: Ranks | AM7: BAB | AN7: Fort | AO7: Reflex | AP7: Will | AQ7: Level
B8: ABILITIES | F8: Score | G8: Modifier | I8: Base | J8: Enhance | K8: Inherent | L8: Temp. | M8: Penalty | O8: HIT POINTS | U8: HP Formula: | V8: Maximum | AD8: SKILLS | AH8: =SUM($AL$9:$AL$45)-if(OR('Welcome Page'!$P$6="Background Skills", 'Welcome Page'!$P$6="Ultimate Psionics + Background Skills")=TRUE,MIN(2*$AQ$6, sum($AL$35:$AL$45)),)&" / "&AL6 -> 42 / 42 | AJ8: Total | AL8: Ranks | AM8: Ability | AN8: Class | AO8: Misc. | AP8: Temp. | AQ8: Size & Armor
E9: STRENGTH | F9: =MAX(0,SUM(I9:L9)-ABS(M9)+iferror(vlookup(E9,'Formula References'!$A$28:$F$34,MATCH($F$5,'Formula References'!$A$28:$F$28,0),false),0)) -> 10 | G9: =MAX(-5,int((F9-10)/2)) -> 0 | H9: = | I9: 10 | L9: =IFERROR(__xludf.DUMMYFUNCTION("SUM(MAX(IFERROR(FILTER(S76:S116,$K76:$K116 = ""ACTIVE"",$G76:$G116 = ""Alchemical"",S76:S116>0)))+SUM(IFERROR(FILTER(S76:S116,$K76:$K116 = ""ACTIVE"",$G76:$G116 = ""Alchemical"",S76:S116<0))), MAX(IFERROR(FILTER(S76:S116,$K76:$K116 = ""ACTIVE"",$G76:$G116"&" = ""Armor"",S76:S116>0)))+SUM(IFERROR(FILTER(S76:S116,$K76:$K116 = ""ACTIVE"",$G76:$G116 = ""Armor"",S76:S116<0))), MAX(IFERROR(FILTER(S76:S116,$K76:$K116 = ""ACTIVE"",$G76:$G116 = ""Competence"",S76:S116>0)))+SUM(IFERROR(FILTER(S76:S116,$K76:$K116 = ""A"&"CTIVE"",$G76:$G116 = ""Competence"",S76:S116<0))), MAX(0,-$J$9+IFERROR(FILTER(S76:S116,$K76:$K116 = ""ACTIVE"",$G76:$G116 = ""Deflect/Enhance/Resist"",S76:S116>0)))+SUM(IFERROR(FILTER(S76:S116,$K76:$K116 = ""ACTIVE"",$G76:$G116 = ""Deflect/Enhance/Resist"&""",S76:S116<0))), MAX(IFERROR(FILTER(S76:S116,$K76:$K116 = ""ACTIVE"",$G76:$G116 = ""Insight"",S76:S116>0)))+SUM(IFERROR(FILTER(S76:S116,$K76:$K116 = ""ACTIVE"",$G76:$G116 = ""Insight"",S76:S116<0))), MAX(IFERROR(FILTER(S76:S116,$K76:$K116 = ""ACTIVE"",$G"&"76:$G116 = ""Luck"",S76:S116>0)))+SUM(IFERROR(FILTER(S76:S116,$K76:$K116 = ""ACTIVE"",$G76:$G116 = ""Luck"",S76:S116<0))), MAX(IFERROR(FILTER(S76:S116,$K76:$K116 = ""ACTIVE"",$G76:$G116 = ""Morale"",S76:S116>0)))+SUM(IFERROR(FILTER(S76:S116,$K76:$K116 = "&"""ACTIVE"",$G76:$G116 = ""Morale"",S76:S116<0))), MAX(IFERROR(FILTER(S76:S116,$K76:$K116 = ""ACTIVE"",$G76:$G116 = ""Precision Damage"",S76:S116>0)))+SUM(IFERROR(FILTER(S76:S116,$K76:$K116 = ""ACTIVE"",$G76:$G116 = ""Precision Damage"",S76:S116<0))), MAX("&"IFERROR(FILTER(S76:S116,$K76:$K116 = ""ACTIVE"",$G76:$G116 = ""Sacred / Profane"",S76:S116>0)))+SUM(IFERROR(FILTER(S76:S116,$K76:$K116 = ""ACTIVE"",$G76:$G116 = ""Sacred / Profane"",S76:S116<0))), MAX(IFERROR(FILTER(S76:S116,$K76:$K116 = ""ACTIVE"",$G76:$"&"G116 = ""Size"",S76:S116>0)))+SUM(IFERROR(FILTER(S76:S116,$K76:$K116 = ""ACTIVE"",$G76:$G116 = ""Size"",S76:S116<0))), SUM(IFERROR(FILTER(S76:S116,$K76:$K116 = ""ACTIVE"",$G76:$G116 = ""Untyped (stacks)"")),), SUM(IFERROR(FILTER(S76:S116,$K76:$K116 = ""AC"&"TIVE"",$G76:$G116 = ""Dodge (stacks)"")),), SUM(IFERROR(FILTER(S76:S116,$K76:$K116 = ""ACTIVE"",$G76:$G116 = ""Circumstance (stacks)"")),)) "),0.0) -> 0 | P9: Defenses | S9: =$AK$6-abs($S$13)-abs($Z$14)-iferror(5*$Y$39,"") & " / " & $AK$6-iferror(5*$Y$39,"") -> 36 / 36 | Z9: Health | AD9: =IF(OR( iferror(vlookup($AE$2, 'Class Skills'!$A:$BE,MATCH(AE9,'Class Skills'!$1:$1,0),false),"")="X", iferror(vlookup($AE$3, 'Class Skills'!$A:$BE,MATCH(AE9,'Class Skills'!$1:$1,0),false),"")="X", iferror(vlookup($AE$4, 'Class Skills'!$A:$BE,MATCH(AE9,'Class Skills'!$1:$1,0),false),"")="X", iferror(vlookup(#REF!, 'Class Skills'!$A:$BE,MATCH(AE9,'Class Skills'!$1:$1,0),false),"")="X"),"X",) -> X | AE9: =Offset('Formula References'!A271,1,Match('Welcome Page'!P6,'Formula References'!A271:E271,0)-1,34) -> Acrobatics | AI9: =HLOOKUP(AE9,'Class Skills'!$1:$3,3,false) -> Dex | AJ9: =if(AND(HLOOKUP(AE9,'Class Skills'!$1:$2,2,false)="Trained Only",AL9<1),,SUM(AL9:AQ9)) -> 9 | AK9: = | AL9: 3 | AM9: =IFERROR(__xludf.DUMMYFUNCTION("offset($E$8,match(AI9,ARRAYFORMULA(Proper(lower(REGEXEXTRACT($E$9:$E$14,""\w\w\w"")))),0),2)"),3.0) -> 3 | AN9: =if(AND(AL9 > 0,AD9 ="X"), 3, ) -> 3 | AP9: =IFERROR(__xludf.DUMMYFUNCTION("if( or(arrayformula(regexmatch($AR$76:$AR$110,AE9))), sum(arrayformula(iferror(value(regexextract(filter( $AR$76:$AR$110, $K$76:$K$110=""ACTIVE"", regexmatch($AR$76:$AR$110,AE9)), ""[-\d]+"")))))+tSkill,tSkill)"),0.0) -> 0 | AQ9: =iferror(if( if(hlookup(AE9,'Class Skills'!$1:$4,4,false)="Armor Penalty",'Formula References'!$Q$156,) +if(AND(isnumber($C$38),AE9="Climb"),8,) +if(AND(isnumber($C$39),AE9="Swim"),8,) +if(AE9="Fly", Vlookup(Size,SizeTable,5,False),) +if(AE9="Fly",if($M$37="Clumsy",-8,if($M$37="Poor",-4,if($M$37="Average",0,if($M$37="Good",4,if($M$37="Perfect",8,0)))))) +if(AE9="Stealth",Vlookup(Size,SizeTable,6,False)) =0,, if(hlookup(AE9,'Class Skills'!$1:$4,4,false)="Armor Penalty",'Formula References'!$Q$156,) +if(AND(isnumber($C$38),AE9="Climb"),8,) +if(AND(isnumber($C$39),AE9="Swim"),8,) +if(AE9="Fly", Vlookup(Size,SizeTable,5,False),) +if(AE9="Fly",if($M$37="Clumsy",-8,if($M$37="Poor",-4,if($M$37="Average",0,if($M$37="Good",4,if($M$37="Perfect",8,0)))))) +if(AE9="Stealth",Vlookup(Size,SizeTable,6,False))),"")
E10: DEXTERITY | F10: =MAX(0,SUM(I10:L10)-ABS(M10)+iferror(vlookup(E10,'Formula References'!$A$28:$F$34,MATCH($F$5,'Formula References'!$A$28:$F$28,0),false),0)) -> 16 | G10: =MAX(-5,int((F10-10)/2)) -> 3 | H10: = | I10: 16 | L10: =IFERROR(__xludf.DUMMYFUNCTION("SUM(MAX(IFERROR(FILTER(T76:T116,$K76:$K116 = ""ACTIVE"",$G76:$G116 = ""Alchemical"",T76:T116>0)))+SUM(IFERROR(FILTER(T76:T116,$K76:$K116 = ""ACTIVE"",$G76:$G116 = ""Alchemical"",T76:T116<0))), MAX(IFERROR(FILTER(T76:T116,$K76:$K116 = ""ACTIVE"",$G76:$G116"&" = ""Armor"",T76:T116>0)))+SUM(IFERROR(FILTER(T76:T116,$K76:$K116 = ""ACTIVE"",$G76:$G116 = ""Armor"",T76:T116<0))), MAX(IFERROR(FILTER(T76:T116,$K76:$K116 = ""ACTIVE"",$G76:$G116 = ""Competence"",T76:T116>0)))+SUM(IFERROR(FILTER(T76:T116,$K76:$K116 = ""A"&"CTIVE"",$G76:$G116 = ""Competence"",T76:T116<0))), MAX(0,-$J$10+IFERROR(FILTER(T76:T116,$K76:$K116 = ""ACTIVE"",$G76:$G116 = ""Deflect/Enhance/Resist"",T76:T116>0)))+SUM(IFERROR(FILTER(T76:T116,$K76:$K116 = ""ACTIVE"",$G76:$G116 = ""Deflect/Enhance/Resist"&""",T76:T116<0))), MAX(IFERROR(FILTER(T76:T116,$K76:$K116 = ""ACTIVE"",$G76:$G116 = ""Insight"",T76:T116>0)))+SUM(IFERROR(FILTER(T76:T116,$K76:$K116 = ""ACTIVE"",$G76:$G116 = ""Insight"",T76:T116<0))), MAX(IFERROR(FILTER(T76:T116,$K76:$K116 = ""ACTIVE"",$G"&"76:$G116 = ""Luck"",T76:T116>0)))+SUM(IFERROR(FILTER(T76:T116,$K76:$K116 = ""ACTIVE"",$G76:$G116 = ""Luck"",T76:T116<0))), MAX(IFERROR(FILTER(T76:T116,$K76:$K116 = ""ACTIVE"",$G76:$G116 = ""Morale"",T76:T116>0)))+SUM(IFERROR(FILTER(T76:T116,$K76:$K116 = "&"""ACTIVE"",$G76:$G116 = ""Morale"",T76:T116<0))), MAX(IFERROR(FILTER(T76:T116,$K76:$K116 = ""ACTIVE"",$G76:$G116 = ""Precision Damage"",T76:T116>0)))+SUM(IFERROR(FILTER(T76:T116,$K76:$K116 = ""ACTIVE"",$G76:$G116 = ""Precision Damage"",T76:T116<0))), MAX("&"IFERROR(FILTER(T76:T116,$K76:$K116 = ""ACTIVE"",$G76:$G116 = ""Sacred / Profane"",T76:T116>0)))+SUM(IFERROR(FILTER(T76:T116,$K76:$K116 = ""ACTIVE"",$G76:$G116 = ""Sacred / Profane"",T76:T116<0))), MAX(IFERROR(FILTER(T76:T116,$K76:$K116 = ""ACTIVE"",$G76:$"&"G116 = ""Size"",T76:T116>0)))+SUM(IFERROR(FILTER(T76:T116,$K76:$K116 = ""ACTIVE"",$G76:$G116 = ""Size"",T76:T116<0))), SUM(IFERROR(FILTER(T76:T116,$K76:$K116 = ""ACTIVE"",$G76:$G116 = ""Untyped (stacks)"")),), SUM(IFERROR(FILTER(T76:T116,$K76:$K116 = ""AC"&"TIVE"",$G76:$G116 = ""Dodge (stacks)"")),), SUM(IFERROR(FILTER(T76:T116,$K76:$K116 = ""ACTIVE"",$G76:$G116 = ""Circumstance (stacks)"")),)) "),0.0) -> 0 | O10: =IFERROR(__xludf.DUMMYFUNCTION("""DR "" & IF( AND(or(arrayformula(regexmatch($AR$74:$AR$116,""DR"")))), MAX(arrayformula(iferror(value(regexextract(filter( $AR$74:$AR$116, $K$74:$K$116=""ACTIVE"", regexmatch($AR$74:$AR$116,""DR"")), ""[-\d]+"")))))&""/"&"""&arrayformula(iferror(regexextract(filter( $AR$74:$AR$116, $K$74:$K$116=""ACTIVE"", regexmatch($AR$74:$AR$116,""DR"")), ""\(([A-Za-z]+)\)""))),""-"") &"" SR "" & IF( AND(or(arrayformula(regexmatch($AR$74:$AR$116,""SR""))))"&", MAX(arrayformula(iferror(value(regexextract(filter( $AR$74:$AR$116, $K$74:$K$116=""ACTIVE"", regexmatch($AR$74:$AR$116,""SR"")), ""[-\d]+""))))),""-"") "),"DR - SR -") -> DR - SR - | AD10: =IF(OR( iferror(vlookup($AE$2, 'Class Skills'!$A:$BE,MATCH(AE10,'Class Skills'!$1:$1,0),false),"")="X", iferror(vlookup($AE$3, 'Class Skills'!$A:$BE,MATCH(AE10,'Class Skills'!$1:$1,0),false),"")="X", iferror(vlookup($AE$4, 'Class Skills'!$A:$BE,MATCH(AE10,'Class Skills'!$1:$1,0),false),"")="X", iferror(vlookup(#REF!, 'Class Skills'!$A:$BE,MATCH(AE10,'Class Skills'!$1:$1,0),false),"")="X"),"X",) -> X | AE10: Bluff | AI10: =HLOOKUP(AE10,'Class Skills'!$1:$3,3,false) -> Cha | AJ10: =if(AND(HLOOKUP(AE10,'Class Skills'!$1:$2,2,false)="Trained Only",AL10<1),,SUM(AL10:AQ10)) -> 6 | AK10: = | AL10: 3 | AM10: =IFERROR(__xludf.DUMMYFUNCTION("offset($E$8,match(AI10,ARRAYFORMULA(Proper(lower(REGEXEXTRACT($E$9:$E$14,""\w\w\w"")))),0),2)"),0.0) -> 0 | AN10: =if(AND(AL10 > 0,AD10 ="X"), 3, ) -> 3 | AP10: =IFERROR(__xludf.DUMMYFUNCTION("if( or(arrayformula(regexmatch($AR$76:$AR$110,AE10))), sum(arrayformula(iferror(value(regexextract(filter( $AR$76:$AR$110, $K$76:$K$110=""ACTIVE"", regexmatch($AR$76:$AR$110,AE10)), ""[-\d]+"")))))+tSkill,tSkill)"),0.0) -> 0 | AQ10: =iferror(if( if(hlookup(AE10,'Class Skills'!$1:$4,4,false)="Armor Penalty",'Formula References'!$Q$156,) +if(AND(isnumber($C$38),AE10="Climb"),8,) +if(AND(isnumber($C$39),AE10="Swim"),8,) +if(AE10="Fly", Vlookup(Size,SizeTable,5,False),) +if(AE10="Fly",if($M$37="Clumsy",-8,if($M$37="Poor",-4,if($M$37="Average",0,if($M$37="Good",4,if($M$37="Perfect",8,0)))))) +if(AE10="Stealth",Vlookup(Size,SizeTable,6,False)) =0,, if(hlookup(AE10,'Class Skills'!$1:$4,4,false)="Armor Penalty",'Formula References'!$Q$156,) +if(AND(isnumber($C$38),AE10="Climb"),8,) +if(AND(isnumber($C$39),AE10="Swim"),8,) +if(AE10="Fly", Vlookup(Size,SizeTable,5,False),) +if(AE10="Fly",if($M$37="Clumsy",-8,if($M$37="Poor",-4,if($M$37="Average",0,if($M$37="Good",4,if($M$37="Perfect",8,0)))))) +if(AE10="Stealth",Vlookup(Size,SizeTable,6,False))),"")
E11: CONSTITUTION | F11: =MAX(0,SUM(I11:L11)-ABS(M11)+iferror(vlookup(E11,'Formula References'!$A$28:$F$34,MATCH($F$5,'Formula References'!$A$28:$F$28,0),false),0)) -> 18 | G11: =MAX(-5,int((F11-10)/2)) -> 4 | H11: = | I11: 18 | L11: =IFERROR(__xludf.DUMMYFUNCTION("SUM(MAX(IFERROR(FILTER(U76:U116,$K76:$K116 = ""ACTIVE"",$G76:$G116 = ""Alchemical"",U76:U116>0)))+SUM(IFERROR(FILTER(U76:U116,$K76:$K116 = ""ACTIVE"",$G76:$G116 = ""Alchemical"",U76:U116<0))), MAX(IFERROR(FILTER(U76:U116,$K76:$K116 = ""ACTIVE"",$G76:$G116"&" = ""Armor"",U76:U116>0)))+SUM(IFERROR(FILTER(U76:U116,$K76:$K116 = ""ACTIVE"",$G76:$G116 = ""Armor"",U76:U116<0))), MAX(IFERROR(FILTER(U76:U116,$K76:$K116 = ""ACTIVE"",$G76:$G116 = ""Competence"",U76:U116>0)))+SUM(IFERROR(FILTER(U76:U116,$K76:$K116 = ""A"&"CTIVE"",$G76:$G116 = ""Competence"",U76:U116<0))), MAX(0,-$J$11+IFERROR(FILTER(U76:U116,$K76:$K116 = ""ACTIVE"",$G76:$G116 = ""Deflect/Enhance/Resist"",U76:U116>0)))+SUM(IFERROR(FILTER(U76:U116,$K76:$K116 = ""ACTIVE"",$G76:$G116 = ""Deflect/Enhance/Resist"&""",U76:U116<0))), MAX(IFERROR(FILTER(U76:U116,$K76:$K116 = ""ACTIVE"",$G76:$G116 = ""Insight"",U76:U116>0)))+SUM(IFERROR(FILTER(U76:U116,$K76:$K116 = ""ACTIVE"",$G76:$G116 = ""Insight"",U76:U116<0))), MAX(IFERROR(FILTER(U76:U116,$K76:$K116 = ""ACTIVE"",$G"&"76:$G116 = ""Luck"",U76:U116>0)))+SUM(IFERROR(FILTER(U76:U116,$K76:$K116 = ""ACTIVE"",$G76:$G116 = ""Luck"",U76:U116<0))), MAX(IFERROR(FILTER(U76:U116,$K76:$K116 = ""ACTIVE"",$G76:$G116 = ""Morale"",U76:U116>0)))+SUM(IFERROR(FILTER(U76:U116,$K76:$K116 = "&"""ACTIVE"",$G76:$G116 = ""Morale"",U76:U116<0))), MAX(IFERROR(FILTER(U76:U116,$K76:$K116 = ""ACTIVE"",$G76:$G116 = ""Precision Damage"",U76:U116>0)))+SUM(IFERROR(FILTER(U76:U116,$K76:$K116 = ""ACTIVE"",$G76:$G116 = ""Precision Damage"",U76:U116<0))), MAX("&"IFERROR(FILTER(U76:U116,$K76:$K116 = ""ACTIVE"",$G76:$G116 = ""Sacred / Profane"",U76:U116>0)))+SUM(IFERROR(FILTER(U76:U116,$K76:$K116 = ""ACTIVE"",$G76:$G116 = ""Sacred / Profane"",U76:U116<0))), MAX(IFERROR(FILTER(U76:U116,$K76:$K116 = ""ACTIVE"",$G76:$"&"G116 = ""Size"",U76:U116>0)))+SUM(IFERROR(FILTER(U76:U116,$K76:$K116 = ""ACTIVE"",$G76:$G116 = ""Size"",U76:U116<0))), SUM(IFERROR(FILTER(U76:U116,$K76:$K116 = ""ACTIVE"",$G76:$G116 = ""Untyped (stacks)"")),), SUM(IFERROR(FILTER(U76:U116,$K76:$K116 = ""AC"&"TIVE"",$G76:$G116 = ""Dodge (stacks)"")),), SUM(IFERROR(FILTER(U76:U116,$K76:$K116 = ""ACTIVE"",$G76:$G116 = ""Circumstance (stacks)"")),)) "),0.0) -> 0 | AD11: =IF(OR( iferror(vlookup($AE$2, 'Class Skills'!$A:$BE,MATCH(AE11,'Class Skills'!$1:$1,0),false),"")="X", iferror(vlookup($AE$3, 'Class Skills'!$A:$BE,MATCH(AE11,'Class Skills'!$1:$1,0),false),"")="X", iferror(vlookup($AE$4, 'Class Skills'!$A:$BE,MATCH(AE11,'Class Skills'!$1:$1,0),false),"")="X", iferror(vlookup(#REF!, 'Class Skills'!$A:$BE,MATCH(AE11,'Class Skills'!$1:$1,0),false),"")="X"),"X",) -> X | AE11: Climb | AI11: =HLOOKUP(AE11,'Class Skills'!$1:$3,3,false) -> Str | AJ11: =if(AND(HLOOKUP(AE11,'Class Skills'!$1:$2,2,false)="Trained Only",AL11<1),,SUM(AL11:AQ11)) -> 0 | AK11: = | AM11: =IFERROR(__xludf.DUMMYFUNCTION("offset($E$8,match(AI11,ARRAYFORMULA(Proper(lower(REGEXEXTRACT($E$9:$E$14,""\w\w\w"")))),0),2)"),0.0) -> 0 | AN11: =if(AND(AL11 > 0,AD11 ="X"), 3, ) | AP11: =IFERROR(__xludf.DUMMYFUNCTION("if( or(arrayformula(regexmatch($AR$76:$AR$110,AE11))), sum(arrayformula(iferror(value(regexextract(filter( $AR$76:$AR$110, $K$76:$K$110=""ACTIVE"", regexmatch($AR$76:$AR$110,AE11)), ""[-\d]+"")))))+tSkill,tSkill)"),0.0) -> 0 | AQ11: =iferror(if( if(hlookup(AE11,'Class Skills'!$1:$4,4,false)="Armor Penalty",'Formula References'!$Q$156,) +if(AND(isnumber($C$38),AE11="Climb"),8,) +if(AND(isnumber($C$39),AE11="Swim"),8,) +if(AE11="Fly", Vlookup(Size,SizeTable,5,False),) +if(AE11="Fly",if($M$37="Clumsy",-8,if($M$37="Poor",-4,if($M$37="Average",0,if($M$37="Good",4,if($M$37="Perfect",8,0)))))) +if(AE11="Stealth",Vlookup(Size,SizeTable,6,False)) =0,, if(hlookup(AE11,'Class Skills'!$1:$4,4,false)="Armor Penalty",'Formula References'!$Q$156,) +if(AND(isnumber($C$38),AE11="Climb"),8,) +if(AND(isnumber($C$39),AE11="Swim"),8,) +if(AE11="Fly", Vlookup(Size,SizeTable,5,False),) +if(AE11="Fly",if($M$37="Clumsy",-8,if($M$37="Poor",-4,if($M$37="Average",0,if($M$37="Good",4,if($M$37="Perfect",8,0)))))) +if(AE11="Stealth",Vlookup(Size,SizeTable,6,False))),"")
E12: INTELLIGENCE | F12: =MAX(0,SUM(I12:L12)-ABS(M12)+iferror(vlookup(E12,'Formula References'!$A$28:$F$34,MATCH($F$5,'Formula References'!$A$28:$F$28,0),false),0)) -> 26 | G12: =MAX(-5,int((F12-10)/2)) -> 8 | H12: = | I12: 26 | L12: =IFERROR(__xludf.DUMMYFUNCTION("SUM(MAX(IFERROR(FILTER(V76:V116,$K76:$K116 = ""ACTIVE"",$G76:$G116 = ""Alchemical"",V76:V116>0)))+SUM(IFERROR(FILTER(V76:V116,$K76:$K116 = ""ACTIVE"",$G76:$G116 = ""Alchemical"",V76:V116<0))), MAX(IFERROR(FILTER(V76:V116,$K76:$K116 = ""ACTIVE"",$G76:$G116"&" = ""Armor"",V76:V116>0)))+SUM(IFERROR(FILTER(V76:V116,$K76:$K116 = ""ACTIVE"",$G76:$G116 = ""Armor"",V76:V116<0))), MAX(IFERROR(FILTER(V76:V116,$K76:$K116 = ""ACTIVE"",$G76:$G116 = ""Competence"",V76:V116>0)))+SUM(IFERROR(FILTER(V76:V116,$K76:$K116 = ""A"&"CTIVE"",$G76:$G116 = ""Competence"",V76:V116<0))), MAX(0,-$J$12+IFERROR(FILTER(V76:V116,$K76:$K116 = ""ACTIVE"",$G76:$G116 = ""Deflect/Enhance/Resist"",V76:V116>0)))+SUM(IFERROR(FILTER(V76:V116,$K76:$K116 = ""ACTIVE"",$G76:$G116 = ""Deflect/Enhance/Resist"&""",V76:V116<0))), MAX(IFERROR(FILTER(V76:V116,$K76:$K116 = ""ACTIVE"",$G76:$G116 = ""Insight"",V76:V116>0)))+SUM(IFERROR(FILTER(V76:V116,$K76:$K116 = ""ACTIVE"",$G76:$G116 = ""Insight"",V76:V116<0))), MAX(IFERROR(FILTER(V76:V116,$K76:$K116 = ""ACTIVE"",$G"&"76:$G116 = ""Luck"",V76:V116>0)))+SUM(IFERROR(FILTER(V76:V116,$K76:$K116 = ""ACTIVE"",$G76:$G116 = ""Luck"",V76:V116<0))), MAX(IFERROR(FILTER(V76:V116,$K76:$K116 = ""ACTIVE"",$G76:$G116 = ""Morale"",V76:V116>0)))+SUM(IFERROR(FILTER(V76:V116,$K76:$K116 = "&"""ACTIVE"",$G76:$G116 = ""Morale"",V76:V116<0))), MAX(IFERROR(FILTER(V76:V116,$K76:$K116 = ""ACTIVE"",$G76:$G116 = ""Precision Damage"",V76:V116>0)))+SUM(IFERROR(FILTER(V76:V116,$K76:$K116 = ""ACTIVE"",$G76:$G116 = ""Precision Damage"",V76:V116<0))), MAX("&"IFERROR(FILTER(V76:V116,$K76:$K116 = ""ACTIVE"",$G76:$G116 = ""Sacred / Profane"",V76:V116>0)))+SUM(IFERROR(FILTER(V76:V116,$K76:$K116 = ""ACTIVE"",$G76:$G116 = ""Sacred / Profane"",V76:V116<0))), MAX(IFERROR(FILTER(V76:V116,$K76:$K116 = ""ACTIVE"",$G76:$"&"G116 = ""Size"",V76:V116>0)))+SUM(IFERROR(FILTER(V76:V116,$K76:$K116 = ""ACTIVE"",$G76:$G116 = ""Size"",V76:V116<0))), SUM(IFERROR(FILTER(V76:V116,$K76:$K116 = ""ACTIVE"",$G76:$G116 = ""Untyped (stacks)"")),), SUM(IFERROR(FILTER(V76:V116,$K76:$K116 = ""AC"&"TIVE"",$G76:$G116 = ""Dodge (stacks)"")),), SUM(IFERROR(FILTER(V76:V116,$K76:$K116 = ""ACTIVE"",$G76:$G116 = ""Circumstance (stacks)"")),)) "),0.0) -> 0 | P12: Resistances | W12: =IFERROR(__xludf.DUMMYFUNCTION("IF($K$116=""ACTIVE"", IF(value(REGEXEXTRACT('Main Sheet'!$S$9,""\d+""))/value(regexextract(regexextract('Main Sheet'!$S$9,""/ \d+""),""\d+""))<0.25,""Critical! -3 to all actions and defenses!"", IF(value(REGEXEXTRACT('Main Sheet'!$S$9,""\d+""))/value(rege"&"xextract(regexextract('Main Sheet'!$S$9,""/ \d+""),""\d+""))<0.5,""Wounded: -2 to all actions and defenses"", IF(value(REGEXEXTRACT('Main Sheet'!$S$9,""\d+""))/value(regexextract(regexextract('Main Sheet'!$S$9,""/ \d+""),""\d+""))<0.75,""Grazed: -1 to all"&" actions and defenses"", ""Healthy: no penalties""))),) "),"") | AD12: =IF(OR( iferror(vlookup($AE$2, 'Class Skills'!$A:$BE,MATCH(AE12,'Class Skills'!$1:$1,0),false),"")="X", iferror(vlookup($AE$3, 'Class Skills'!$A:$BE,MATCH(AE12,'Class Skills'!$1:$1,0),false),"")="X", iferror(vlookup($AE$4, 'Class Skills'!$A:$BE,MATCH(AE12,'Class Skills'!$1:$1,0),false),"")="X", iferror(vlookup(#REF!, 'Class Skills'!$A:$BE,MATCH(AE12,'Class Skills'!$1:$1,0),false),"")="X"),"X",) -> X | AE12: Diplomacy | AI12: =HLOOKUP(AE12,'Class Skills'!$1:$3,3,false) -> Cha | AJ12: =if(AND(HLOOKUP(AE12,'Class Skills'!$1:$2,2,false)="Trained Only",AL12<1),,SUM(AL12:AQ12)) -> 6 | AK12: = | AL12: 3 | AM12: =IFERROR(__xludf.DUMMYFUNCTION("offset($E$8,match(AI12,ARRAYFORMULA(Proper(lower(REGEXEXTRACT($E$9:$E$14,""\w\w\w"")))),0),2)"),0.0) -> 0 | AN12: =if(AND(AL12 > 0,AD12 ="X"), 3, ) -> 3 | AP12: =IFERROR(__xludf.DUMMYFUNCTION("if( or(arrayformula(regexmatch($AR$76:$AR$110,AE12))), sum(arrayformula(iferror(value(regexextract(filter( $AR$76:$AR$110, $K$76:$K$110=""ACTIVE"", regexmatch($AR$76:$AR$110,AE12)), ""[-\d]+"")))))+tSkill,tSkill)"),0.0) -> 0 | AQ12: =iferror(if( if(hlookup(AE12,'Class Skills'!$1:$4,4,false)="Armor Penalty",'Formula References'!$Q$156,) +if(AND(isnumber($C$38),AE12="Climb"),8,) +if(AND(isnumber($C$39),AE12="Swim"),8,) +if(AE12="Fly", Vlookup(Size,SizeTable,5,False),) +if(AE12="Fly",if($M$37="Clumsy",-8,if($M$37="Poor",-4,if($M$37="Average",0,if($M$37="Good",4,if($M$37="Perfect",8,0)))))) +if(AE12="Stealth",Vlookup(Size,SizeTable,6,False)) =0,, if(hlookup(AE12,'Class Skills'!$1:$4,4,false)="Armor Penalty",'Formula References'!$Q$156,) +if(AND(isnumber($C$38),AE12="Climb"),8,) +if(AND(isnumber($C$39),AE12="Swim"),8,) +if(AE12="Fly", Vlookup(Size,SizeTable,5,False),) +if(AE12="Fly",if($M$37="Clumsy",-8,if($M$37="Poor",-4,if($M$37="Average",0,if($M$37="Good",4,if($M$37="Perfect",8,0)))))) +if(AE12="Stealth",Vlookup(Size,SizeTable,6,False))),"")
E13: WISDOM | F13: =MAX(0,SUM(I13:L13)-ABS(M13)+iferror(vlookup(E13,'Formula References'!$A$28:$F$34,MATCH($F$5,'Formula References'!$A$28:$F$28,0),false),0)) -> 10 | G13: =MAX(-5,int((F13-10)/2)) -> 0 | H13: = | I13: 10 | L13: =IFERROR(__xludf.DUMMYFUNCTION("SUM(MAX(IFERROR(FILTER(W76:W116,$K76:$K116 = ""ACTIVE"",$G76:$G116 = ""Alchemical"",W76:W116>0)))+SUM(IFERROR(FILTER(W76:W116,$K76:$K116 = ""ACTIVE"",$G76:$G116 = ""Alchemical"",W76:W116<0))), MAX(IFERROR(FILTER(W76:W116,$K76:$K116 = ""ACTIVE"",$G76:$G116"&" = ""Armor"",W76:W116>0)))+SUM(IFERROR(FILTER(W76:W116,$K76:$K116 = ""ACTIVE"",$G76:$G116 = ""Armor"",W76:W116<0))), MAX(IFERROR(FILTER(W76:W116,$K76:$K116 = ""ACTIVE"",$G76:$G116 = ""Competence"",W76:W116>0)))+SUM(IFERROR(FILTER(W76:W116,$K76:$K116 = ""A"&"CTIVE"",$G76:$G116 = ""Competence"",W76:W116<0))), MAX(0,-$J$13+IFERROR(FILTER(W76:W116,$K76:$K116 = ""ACTIVE"",$G76:$G116 = ""Deflect/Enhance/Resist"",W76:W116>0)))+SUM(IFERROR(FILTER(W76:W116,$K76:$K116 = ""ACTIVE"",$G76:$G116 = ""Deflect/Enhance/Resist"&""",W76:W116<0))), MAX(IFERROR(FILTER(W76:W116,$K76:$K116 = ""ACTIVE"",$G76:$G116 = ""Insight"",W76:W116>0)))+SUM(IFERROR(FILTER(W76:W116,$K76:$K116 = ""ACTIVE"",$G76:$G116 = ""Insight"",W76:W116<0))), MAX(IFERROR(FILTER(W76:W116,$K76:$K116 = ""ACTIVE"",$G"&"76:$G116 = ""Luck"",W76:W116>0)))+SUM(IFERROR(FILTER(W76:W116,$K76:$K116 = ""ACTIVE"",$G76:$G116 = ""Luck"",W76:W116<0))), MAX(IFERROR(FILTER(W76:W116,$K76:$K116 = ""ACTIVE"",$G76:$G116 = ""Morale"",W76:W116>0)))+SUM(IFERROR(FILTER(W76:W116,$K76:$K116 = "&"""ACTIVE"",$G76:$G116 = ""Morale"",W76:W116<0))), MAX(IFERROR(FILTER(W76:W116,$K76:$K116 = ""ACTIVE"",$G76:$G116 = ""Precision Damage"",W76:W116>0)))+SUM(IFERROR(FILTER(W76:W116,$K76:$K116 = ""ACTIVE"",$G76:$G116 = ""Precision Damage"",W76:W116<0))), MAX("&"IFERROR(FILTER(W76:W116,$K76:$K116 = ""ACTIVE"",$G76:$G116 = ""Sacred / Profane"",W76:W116>0)))+SUM(IFERROR(FILTER(W76:W116,$K76:$K116 = ""ACTIVE"",$G76:$G116 = ""Sacred / Profane"",W76:W116<0))), MAX(IFERROR(FILTER(W76:W116,$K76:$K116 = ""ACTIVE"",$G76:$"&"G116 = ""Size"",W76:W116>0)))+SUM(IFERROR(FILTER(W76:W116,$K76:$K116 = ""ACTIVE"",$G76:$G116 = ""Size"",W76:W116<0))), SUM(IFERROR(FILTER(W76:W116,$K76:$K116 = ""ACTIVE"",$G76:$G116 = ""Untyped (stacks)"")),), SUM(IFERROR(FILTER(W76:W116,$K76:$K116 = ""AC"&"TIVE"",$G76:$G116 = ""Dodge (stacks)"")),), SUM(IFERROR(FILTER(W76:W116,$K76:$K116 = ""ACTIVE"",$G76:$G116 = ""Circumstance (stacks)"")),)) "),0.0) -> 0 | O13: =IFERROR(__xludf.DUMMYFUNCTION("""Fire "" & IF( AND(or(arrayformula(regexmatch($AR$74:$AR$116,""Resistance""))), or(arrayformula(regexmatch($AR$74:$AR$116,""Fire"")))), MAX(arrayformula(iferror(value(regexextract(filter( $AR$74:$AR$116, $K$74:$K$116=""ACTIVE"", "&" regexmatch($AR$74:$AR$116,""Resistance""), regexmatch($AR$74:$AR$116,""Fire"")), ""[-\d]+""))))),""0"") & "" Cold "" & IF( AND(or(arrayformula(regexmatch($AR$74:$AR$116,""Resistance""))), or(arrayformula(regexmatch($AR$74:$AR$116,""Co"&"ld"")))), MAX(arrayformula(iferror(value(regexextract(filter( $AR$74:$AR$116, $K$74:$K$116=""ACTIVE"", regexmatch($AR$74:$AR$116,""Resistance""), regexmatch($AR$74:$AR$116,""Cold"")), ""[-\d]+""))))),""0"") & """&" Acid "" & IF( AND(or(arrayformula(regexmatch($AR$74:$AR$116,""Resistance""))), or(arrayformula(regexmatch($AR$74:$AR$116,""Acid"")))), MAX(arrayformula(iferror(value(regexextract(filter( $AR$74:$AR$116, $K$74:$K$116=""ACTIVE"", "&" regexmatch($AR$74:$AR$116,""Resistance""), regexmatch($AR$74:$AR$116,""Acid"")), ""[-\d]+""))))),""0"") & "" Elect "" & IF( AND(or(arrayformula(regexmatch($AR$74:$AR$116,""Resistance""))), or(arrayformula(regexmatch($AR$74:$AR$116,""Ele"&"ctricity"")))), MAX(arrayformula(iferror(value(regexextract(filter( $AR$74:$AR$116, $K$74:$K$116=""ACTIVE"", regexmatch($AR$74:$AR$116,""Resistance""), regexmatch($AR$74:$AR$116,""Electricity"")), ""[-\d]+""))))"&"),""0"")"),"Fire 0 Cold 0 Acid 0 Elect 0") -> Fire 0 Cold 0 Acid 0 Elect 0 | W13: Damage | AB13: Nonlethal | AD13: =IF(OR( iferror(vlookup($AE$2, 'Class Skills'!$A:$BE,MATCH(AE13,'Class Skills'!$1:$1,0),false),"")="X", iferror(vlookup($AE$3, 'Class Skills'!$A:$BE,MATCH(AE13,'Class Skills'!$1:$1,0),false),"")="X", iferror(vlookup($AE$4, 'Class Skills'!$A:$BE,MATCH(AE13,'Class Skills'!$1:$1,0),false),"")="X", iferror(vlookup(#REF!, 'Class Skills'!$A:$BE,MATCH(AE13,'Class Skills'!$1:$1,0),false),"")="X"),"X",) -> X | AE13: Disable Device | AI13: =HLOOKUP(AE13,'Class Skills'!$1:$3,3,false) -> Dex | AJ13: =if(AND(HLOOKUP(AE13,'Class Skills'!$1:$2,2,false)="Trained Only",AL13<1),,SUM(AL13:AQ13)) | AK13: = | AM13: =IFERROR(__xludf.DUMMYFUNCTION("offset($E$8,match(AI13,ARRAYFORMULA(Proper(lower(REGEXEXTRACT($E$9:$E$14,""\w\w\w"")))),0),2)"),3.0) -> 3 | AN13: =if(AND(AL13 > 0,AD13 ="X"), 3, ) | AP13: =IFERROR(__xludf.DUMMYFUNCTION("if( or(arrayformula(regexmatch($AR$76:$AR$110,AE13))), sum(arrayformula(iferror(value(regexextract(filter( $AR$76:$AR$110, $K$76:$K$110=""ACTIVE"", regexmatch($AR$76:$AR$110,AE13)), ""[-\d]+"")))))+tSkill,tSkill)"),0.0) -> 0 | AQ13: =iferror(if( if(hlookup(AE13,'Class Skills'!$1:$4,4,false)="Armor Penalty",'Formula References'!$Q$156,) +if(AND(isnumber($C$38),AE13="Climb"),8,) +if(AND(isnumber($C$39),AE13="Swim"),8,) +if(AE13="Fly", Vlookup(Size,SizeTable,5,False),) +if(AE13="Fly",if($M$37="Clumsy",-8,if($M$37="Poor",-4,if($M$37="Average",0,if($M$37="Good",4,if($M$37="Perfect",8,0)))))) +if(AE13="Stealth",Vlookup(Size,SizeTable,6,False)) =0,, if(hlookup(AE13,'Class Skills'!$1:$4,4,false)="Armor Penalty",'Formula References'!$Q$156,) +if(AND(isnumber($C$38),AE13="Climb"),8,) +if(AND(isnumber($C$39),AE13="Swim"),8,) +if(AE13="Fly", Vlookup(Size,SizeTable,5,False),) +if(AE13="Fly",if($M$37="Clumsy",-8,if($M$37="Poor",-4,if($M$37="Average",0,if($M$37="Good",4,if($M$37="Perfect",8,0)))))) +if(AE13="Stealth",Vlookup(Size,SizeTable,6,False))),"")
E14: CHARISMA | F14: =MAX(0,SUM(I14:L14)-ABS(M14)+iferror(vlookup(E14,'Formula References'!$A$28:$F$34,MATCH($F$5,'Formula References'!$A$28:$F$28,0),false),0)) -> 10 | G14: =MAX(-5,int((F14-10)/2)) -> 0 | H14: = | I14: 10 | L14: =IFERROR(__xludf.DUMMYFUNCTION("SUM(MAX(IFERROR(FILTER(X76:X116,$K76:$K116 = ""ACTIVE"",$G76:$G116 = ""Alchemical"",X76:X116>0)))+SUM(IFERROR(FILTER(X76:X116,$K76:$K116 = ""ACTIVE"",$G76:$G116 = ""Alchemical"",X76:X116<0))), MAX(IFERROR(FILTER(X76:X116,$K76:$K116 = ""ACTIVE"",$G76:$G116"&" = ""Armor"",X76:X116>0)))+SUM(IFERROR(FILTER(X76:X116,$K76:$K116 = ""ACTIVE"",$G76:$G116 = ""Armor"",X76:X116<0))), MAX(IFERROR(FILTER(X76:X116,$K76:$K116 = ""ACTIVE"",$G76:$G116 = ""Competence"",X76:X116>0)))+SUM(IFERROR(FILTER(X76:X116,$K76:$K116 = ""A"&"CTIVE"",$G76:$G116 = ""Competence"",X76:X116<0))), MAX(0,-$J$14+IFERROR(FILTER(X76:X116,$K76:$K116 = ""ACTIVE"",$G76:$G116 = ""Deflect/Enhance/Resist"",X76:X116>0)))+SUM(IFERROR(FILTER(X76:X116,$K76:$K116 = ""ACTIVE"",$G76:$G116 = ""Deflect/Enhance/Resist"&""",X76:X116<0))), MAX(IFERROR(FILTER(X76:X116,$K76:$K116 = ""ACTIVE"",$G76:$G116 = ""Insight"",X76:X116>0)))+SUM(IFERROR(FILTER(X76:X116,$K76:$K116 = ""ACTIVE"",$G76:$G116 = ""Insight"",X76:X116<0))), MAX(IFERROR(FILTER(X76:X116,$K76:$K116 = ""ACTIVE"",$G"&"76:$G116 = ""Luck"",X76:X116>0)))+SUM(IFERROR(FILTER(X76:X116,$K76:$K116 = ""ACTIVE"",$G76:$G116 = ""Luck"",X76:X116<0))), MAX(IFERROR(FILTER(X76:X116,$K76:$K116 = ""ACTIVE"",$G76:$G116 = ""Morale"",X76:X116>0)))+SUM(IFERROR(FILTER(X76:X116,$K76:$K116 = "&"""ACTIVE"",$G76:$G116 = ""Morale"",X76:X116<0))), MAX(IFERROR(FILTER(X76:X116,$K76:$K116 = ""ACTIVE"",$G76:$G116 = ""Precision Damage"",X76:X116>0)))+SUM(IFERROR(FILTER(X76:X116,$K76:$K116 = ""ACTIVE"",$G76:$G116 = ""Precision Damage"",X76:X116<0))), MAX("&"IFERROR(FILTER(X76:X116,$K76:$K116 = ""ACTIVE"",$G76:$G116 = ""Sacred / Profane"",X76:X116>0)))+SUM(IFERROR(FILTER(X76:X116,$K76:$K116 = ""ACTIVE"",$G76:$G116 = ""Sacred / Profane"",X76:X116<0))), MAX(IFERROR(FILTER(X76:X116,$K76:$K116 = ""ACTIVE"",$G76:$"&"G116 = ""Size"",X76:X116>0)))+SUM(IFERROR(FILTER(X76:X116,$K76:$K116 = ""ACTIVE"",$G76:$G116 = ""Size"",X76:X116<0))), SUM(IFERROR(FILTER(X76:X116,$K76:$K116 = ""ACTIVE"",$G76:$G116 = ""Untyped (stacks)"")),), SUM(IFERROR(FILTER(X76:X116,$K76:$K116 = ""AC"&"TIVE"",$G76:$G116 = ""Dodge (stacks)"")),), SUM(IFERROR(FILTER(X76:X116,$K76:$K116 = ""ACTIVE"",$G76:$G116 = ""Circumstance (stacks)"")),)) "),0.0) -> 0 | AD14: =IF(OR( iferror(vlookup($AE$2, 'Class Skills'!$A:$BE,MATCH(AE14,'Class Skills'!$1:$1,0),false),"")="X", iferror(vlookup($AE$3, 'Class Skills'!$A:$BE,MATCH(AE14,'Class Skills'!$1:$1,0),false),"")="X", iferror(vlookup($AE$4, 'Class Skills'!$A:$BE,MATCH(AE14,'Class Skills'!$1:$1,0),false),"")="X", iferror(vlookup(#REF!, 'Class Skills'!$A:$BE,MATCH(AE14,'Class Skills'!$1:$1,0),false),"")="X"),"X",) -> X | AE14: Disguise | AI14: =HLOOKUP(AE14,'Class Skills'!$1:$3,3,false) -> Cha | AJ14: =if(AND(HLOOKUP(AE14,'Class Skills'!$1:$2,2,false)="Trained Only",AL14<1),,SUM(AL14:AQ14)) -> 6 | AK14: = | AL14: 3 | AM14: =IFERROR(__xludf.DUMMYFUNCTION("offset($E$8,match(AI14,ARRAYFORMULA(Proper(lower(REGEXEXTRACT($E$9:$E$14,""\w\w\w"")))),0),2)"),0.0) -> 0 | AN14: =if(AND(AL14 > 0,AD14 ="X"), 3, ) -> 3 | AP14: =IFERROR(__xludf.DUMMYFUNCTION("if( or(arrayformula(regexmatch($AR$76:$AR$110,AE14))), sum(arrayformula(iferror(value(regexextract(filter( $AR$76:$AR$110, $K$76:$K$110=""ACTIVE"", regexmatch($AR$76:$AR$110,AE14)), ""[-\d]+"")))))+tSkill,tSkill)"),0.0) -> 0 | AQ14: =iferror(if( if(hlookup(AE14,'Class Skills'!$1:$4,4,false)="Armor Penalty",'Formula References'!$Q$156,) +if(AND(isnumber($C$38),AE14="Climb"),8,) +if(AND(isnumber($C$39),AE14="Swim"),8,) +if(AE14="Fly", Vlookup(Size,SizeTable,5,False),) +if(AE14="Fly",if($M$37="Clumsy",-8,if($M$37="Poor",-4,if($M$37="Average",0,if($M$37="Good",4,if($M$37="Perfect",8,0)))))) +if(AE14="Stealth",Vlookup(Size,SizeTable,6,False)) =0,, if(hlookup(AE14,'Class Skills'!$1:$4,4,false)="Armor Penalty",'Formula References'!$Q$156,) +if(AND(isnumber($C$38),AE14="Climb"),8,) +if(AND(isnumber($C$39),AE14="Swim"),8,) +if(AE14="Fly", Vlookup(Size,SizeTable,5,False),) +if(AE14="Fly",if($M$37="Clumsy",-8,if($M$37="Poor",-4,if($M$37="Average",0,if($M$37="Good",4,if($M$37="Perfect",8,0)))))) +if(AE14="Stealth",Vlookup(Size,SizeTable,6,False))),"")
AD15: =IF(OR( iferror(vlookup($AE$2, 'Class Skills'!$A:$BE,MATCH(AE15,'Class Skills'!$1:$1,0),false),"")="X", iferror(vlookup($AE$3, 'Class Skills'!$A:$BE,MATCH(AE15,'Class Skills'!$1:$1,0),false),"")="X", iferror(vlookup($AE$4, 'Class Skills'!$A:$BE,MATCH(AE15,'Class Skills'!$1:$1,0),false),"")="X", iferror(vlookup(#REF!, 'Class Skills'!$A:$BE,MATCH(AE15,'Class Skills'!$1:$1,0),false),"")="X"),"X",) -> X | AE15: Escape Artist | AI15: =HLOOKUP(AE15,'Class Skills'!$1:$3,3,false) -> Dex | AJ15: =if(AND(HLOOKUP(AE15,'Class Skills'!$1:$2,2,false)="Trained Only",AL15<1),,SUM(AL15:AQ15)) -> 9 | AK15: = | AL15: 3 | AM15: =IFERROR(__xludf.DUMMYFUNCTION("offset($E$8,match(AI15,ARRAYFORMULA(Proper(lower(REGEXEXTRACT($E$9:$E$14,""\w\w\w"")))),0),2)"),3.0) -> 3 | AN15: =if(AND(AL15 > 0,AD15 ="X"), 3, ) -> 3 | AP15: =IFERROR(__xludf.DUMMYFUNCTION("if( or(arrayformula(regexmatch($AR$76:$AR$110,AE15))), sum(arrayformula(iferror(value(regexextract(filter( $AR$76:$AR$110, $K$76:$K$110=""ACTIVE"", regexmatch($AR$76:$AR$110,AE15)), ""[-\d]+"")))))+tSkill,tSkill)"),0.0) -> 0 | AQ15: =iferror(if( if(hlookup(AE15,'Class Skills'!$1:$4,4,false)="Armor Penalty",'Formula References'!$Q$156,) +if(AND(isnumber($C$38),AE15="Climb"),8,) +if(AND(isnumber($C$39),AE15="Swim"),8,) +if(AE15="Fly", Vlookup(Size,SizeTable,5,False),) +if(AE15="Fly",if($M$37="Clumsy",-8,if($M$37="Poor",-4,if($M$37="Average",0,if($M$37="Good",4,if($M$37="Perfect",8,0)))))) +if(AE15="Stealth",Vlookup(Size,SizeTable,6,False)) =0,, if(hlookup(AE15,'Class Skills'!$1:$4,4,false)="Armor Penalty",'Formula References'!$Q$156,) +if(AND(isnumber($C$38),AE15="Climb"),8,) +if(AND(isnumber($C$39),AE15="Swim"),8,) +if(AE15="Fly", Vlookup(Size,SizeTable,5,False),) +if(AE15="Fly",if($M$37="Clumsy",-8,if($M$37="Poor",-4,if($M$37="Average",0,if($M$37="Good",4,if($M$37="Perfect",8,0)))))) +if(AE15="Stealth",Vlookup(Size,SizeTable,6,False))),"")
B16: SAVES | F16: Total | H16: Base | I16: Ability | J16: Resist | K16: Misc. | L16: Temp. | O16: DEFENSES | R16: Total | T16: Armor | U16: Shield | V16: Dex | W16: Size | X16: Natural | Y16: Deflect | Z16: Dodge | AA16: Misc. | AB16: Temp. | AD16: =IF(OR( iferror(vlookup($AE$2, 'Class Skills'!$A:$BE,MATCH(AE16,'Class Skills'!$1:$1,0),false),"")="X", iferror(vlookup($AE$3, 'Class Skills'!$A:$BE,MATCH(AE16,'Class Skills'!$1:$1,0),false),"")="X", iferror(vlookup($AE$4, 'Class Skills'!$A:$BE,MATCH(AE16,'Class Skills'!$1:$1,0),false),"")="X", iferror(vlookup(#REF!, 'Class Skills'!$A:$BE,MATCH(AE16,'Class Skills'!$1:$1,0),false),"")="X"),"X",) | AE16: Fly | AI16: =HLOOKUP(AE16,'Class Skills'!$1:$3,3,false) -> Dex | AJ16: =if(AND(HLOOKUP(AE16,'Class Skills'!$1:$2,2,false)="Trained Only",AL16<1),,SUM(AL16:AQ16)) -> 3 | AK16: = | AM16: =IFERROR(__xludf.DUMMYFUNCTION("offset($E$8,match(AI16,ARRAYFORMULA(Proper(lower(REGEXEXTRACT($E$9:$E$14,""\w\w\w"")))),0),2)"),3.0) -> 3 | AN16: =if(AND(AL16 > 0,AD16 ="X"), 3, ) | AP16: =IFERROR(__xludf.DUMMYFUNCTION("if( or(arrayformula(regexmatch($AR$76:$AR$110,AE16))), sum(arrayformula(iferror(value(regexextract(filter( $AR$76:$AR$110, $K$76:$K$110=""ACTIVE"", regexmatch($AR$76:$AR$110,AE16)), ""[-\d]+"")))))+tSkill,tSkill)"),0.0) -> 0 | AQ16: =iferror(if( if(hlookup(AE16,'Class Skills'!$1:$4,4,false)="Armor Penalty",'Formula References'!$Q$156,) +if(AND(isnumber($C$38),AE16="Climb"),8,) +if(AND(isnumber($C$39),AE16="Swim"),8,) +if(AE16="Fly", Vlookup(Size,SizeTable,5,False),) +if(AE16="Fly",if($M$37="Clumsy",-8,if($M$37="Poor",-4,if($M$37="Average",0,if($M$37="Good",4,if($M$37="Perfect",8,0)))))) +if(AE16="Stealth",Vlookup(Size,SizeTable,6,False)) =0,, if(hlookup(AE16,'Class Skills'!$1:$4,4,false)="Armor Penalty",'Formula References'!$Q$156,) +if(AND(isnumber($C$38),AE16="Climb"),8,) +if(AND(isnumber($C$39),AE16="Swim"),8,) +if(AE16="Fly", Vlookup(Size,SizeTable,5,False),) +if(AE16="Fly",if($M$37="Clumsy",-8,if($M$37="Poor",-4,if($M$37="Average",0,if($M$37="Good",4,if($M$37="Perfect",8,0)))))) +if(AE16="Stealth",Vlookup(Size,SizeTable,6,False))),"")
E17: FORTITUDE | F17: =SUM(H17:L17) -> 7 | G17: = | H17: =AN6 -> 3 | I17: =Constitution -> 4 | J17: =IFERROR(__xludf.DUMMYFUNCTION("SUM( MAX(IFERROR(FILTER(P76:P116,$K76:$K116 = ""ACTIVE"",$G76:$G116 = ""Deflect/Enhance/Resist"",P76:P116>0))) +SUM(IFERROR(FILTER(P76:P116,$K76:$K116 = ""ACTIVE"",$G76:$G116 = ""Deflect/Enhance/Resist"",P76:P116<0))) )"),0.0) -> 0 | L17: =IFERROR(__xludf.DUMMYFUNCTION("SUM(MAX(IFERROR(FILTER(P76:P116,$K76:$K116 = ""ACTIVE"",$G76:$G116 = ""Alchemical"",P76:P116>0)))+SUM(IFERROR(FILTER(P76:P116,$K76:$K116 = ""ACTIVE"",$G76:$G116 = ""Alchemical"",P76:P116<0))), MAX(IFERROR(FILTER(P76:P116,$K76:$K116 = ""ACTIVE"",$G76:$G116"&" = ""Armor"",P76:P116>0)))+SUM(IFERROR(FILTER(P76:P116,$K76:$K116 = ""ACTIVE"",$G76:$G116 = ""Armor"",P76:P116<0))), MAX(IFERROR(FILTER(P76:P116,$K76:$K116 = ""ACTIVE"",$G76:$G116 = ""Competence"",P76:P116>0)))+SUM(IFERROR(FILTER(P76:P116,$K76:$K116 = ""A"&"CTIVE"",$G76:$G116 = ""Competence"",P76:P116<0))), MAX(IFERROR(FILTER(P76:P116,$K76:$K116 = ""ACTIVE"",$G76:$G116 = ""Insight"",P76:P116>0)))+SUM(IFERROR(FILTER(P76:P116,$K76:$K116 = ""ACTIVE"",$G76:$G116 = ""Insight"",P76:P116<0))), MAX(IFERROR(FILTER(P7"&"6:P116,$K76:$K116 = ""ACTIVE"",$G76:$G116 = ""Luck"",P76:P116>0)))+SUM(IFERROR(FILTER(P76:P116,$K76:$K116 = ""ACTIVE"",$G76:$G116 = ""Luck"",P76:P116<0))), MAX(IFERROR(FILTER(P76:P116,$K76:$K116 = ""ACTIVE"",$G76:$G116 = ""Morale"",P76:P116>0)))+SUM(IFERR"&"OR(FILTER(P76:P116,$K76:$K116 = ""ACTIVE"",$G76:$G116 = ""Morale"",P76:P116<0))), MAX(IFERROR(FILTER(P76:P116,$K76:$K116 = ""ACTIVE"",$G76:$G116 = ""Precision Damage"",P76:P116>0)))+SUM(IFERROR(FILTER(P76:P116,$K76:$K116 = ""ACTIVE"",$G76:$G116 = ""Precis"&"ion Damage"",P76:P116<0))), MAX(IFERROR(FILTER(P76:P116,$K76:$K116 = ""ACTIVE"",$G76:$G116 = ""Sacred / Profane"",P76:P116>0)))+SUM(IFERROR(FILTER(P76:P116,$K76:$K116 = ""ACTIVE"",$G76:$G116 = ""Sacred / Profane"",P76:P116<0))), MAX(IFERROR(FILTER(P76:P11"&"6,$K76:$K116 = ""ACTIVE"",$G76:$G116 = ""Size"",P76:P116>0)))+SUM(IFERROR(FILTER(P76:P116,$K76:$K116 = ""ACTIVE"",$G76:$G116 = ""Size"",P76:P116<0))), SUM(IFERROR(FILTER(P76:P116,$K76:$K116 = ""ACTIVE"",$G76:$G116 = ""Untyped (stacks)"")),), SUM(IFERROR(F"&"ILTER(P76:P116,$K76:$K116 = ""ACTIVE"",$G76:$G116 = ""Dodge (stacks)"")),), SUM(IFERROR(FILTER(P76:P116,$K76:$K116 = ""ACTIVE"",$G76:$G116 = ""Circumstance (stacks)"")),))"),0.0) -> 0 | Q17: ARMOR CLASS | R17: =10+SUM(T17:AB17) -> 21 | S17: = | T17: =IFERROR(__xludf.DUMMYFUNCTION("MAX($O$42,MAX(IFERROR(FILTER(N76:N116,$K76:$K116 = ""ACTIVE"",$G76:$G116 = ""Armor"",N76:N116>0)))) +SUM(IFERROR(FILTER(N76:N116,$K76:$K116 = ""ACTIVE"",$G76:$G116 = ""Armor"",N76:N116<0)))+SUM(IFERROR(FILTER(N76:N116,$K76:$K116 = ""ACTIVE"",$G76:$G116 = "&"""Bonus AC (Stacks)"",N76:N116>0)))"),0.0) -> 0 | U17: =O43 -> 0 | V17: =Min(Dexterity,'Formula References'!$P$156) -> 3 | W17: =VLOOKUP(Size,SizeTable,3,false) -> 0 | X17: =$O$74 -> 0 | Y17: =IFERROR(__xludf.DUMMYFUNCTION(" MAX(IFERROR(FILTER(N76:N116,$K76:$K116 = ""ACTIVE"",$G76:$G116 = ""Deflect/Enhance/Resist"",N76:N116>0)))+SUM(IFERROR(FILTER(N76:N116,$K76:$K116 = ""ACTIVE"",$G76:$G116 = ""Deflect/Enhance/Resist"",N76:N116<0)))"),0.0) -> 0 | Z17: =IFERROR(__xludf.DUMMYFUNCTION(" SUM(IFERROR(FILTER(N76:N116,$K76:$K116 = ""ACTIVE"",$G76:$G116 = ""Dodge (stacks)"")),)"),8.0) -> 8 | AB17: =IFERROR(__xludf.DUMMYFUNCTION("SUM(MAX(IFERROR(FILTER(N76:N116,$K76:$K116 = ""ACTIVE"",$G76:$G116 = ""Alchemical"",N76:N116>0)))+SUM(IFERROR(FILTER(N76:N116,$K76:$K116 = ""ACTIVE"",$G76:$G116 = ""Alchemical"",N76:N116<0))), MAX(IFERROR(FILTER(N76:N116,$K76:$K116 = ""ACTIVE"",$G76:$G116"&" = ""Competence"",N76:N116>0)))+SUM(IFERROR(FILTER(N76:N116,$K76:$K116 = ""ACTIVE"",$G76:$G116 = ""Competence"",N76:N116<0))), MAX(IFERROR(FILTER(N76:N116,$K76:$K116 = ""ACTIVE"",$G76:$G116 = ""Insight"",N76:N116>0)))+SUM(IFERROR(FILTER(N76:N116,$K76:$K11"&"6 = ""ACTIVE"",$G76:$G116 = ""Insight"",N76:N116<0))), MAX(IFERROR(FILTER(N76:N116,$K76:$K116 = ""ACTIVE"",$G76:$G116 = ""Luck"",N76:N116>0)))+SUM(IFERROR(FILTER(N76:N116,$K76:$K116 = ""ACTIVE"",$G76:$G116 = ""Luck"",N76:N116<0))), MAX(IFERROR(FILTER(N76:"&"N116,$K76:$K116 = ""ACTIVE"",$G76:$G116 = ""Morale"",N76:N116>0)))+SUM(IFERROR(FILTER(N76:N116,$K76:$K116 = ""ACTIVE"",$G76:$G116 = ""Morale"",N76:N116<0))), MAX(IFERROR(FILTER(N76:N116,$K76:$K116 = ""ACTIVE"",$G76:$G116 = ""Precision Damage"",N76:N116>0)"&"))+SUM(IFERROR(FILTER(N76:N116,$K76:$K116 = ""ACTIVE"",$G76:$G116 = ""Precision Damage"",N76:N116<0))), MAX(IFERROR(FILTER(N76:N116,$K76:$K116 = ""ACTIVE"",$G76:$G116 = ""Sacred / Profane"",N76:N116>0)))+SUM(IFERROR(FILTER(N76:N116,$K76:$K116 = ""ACTIVE"""&",$G76:$G116 = ""Sacred / Profane"",N76:N116<0))), SUM(IFERROR(FILTER(N76:N116,$K76:$K116 = ""ACTIVE"",$G76:$G116 = ""Untyped (stacks)"")),), SUM(IFERROR(FILTER(N76:N116,$K76:$K116 = ""ACTIVE"",$G76:$G116 = ""Circumstance (stacks)"")),))"),0.0) -> 0 | AD17: =IF(OR( iferror(vlookup($AE$2, 'Class Skills'!$A:$BE,MATCH(AE17,'Class Skills'!$1:$1,0),false),"")="X", iferror(vlookup($AE$3, 'Class Skills'!$A:$BE,MATCH(AE17,'Class Skills'!$1:$1,0),false),"")="X", iferror(vlookup($AE$4, 'Class Skills'!$A:$BE,MATCH(AE17,'Class Skills'!$1:$1,0),false),"")="X", iferror(vlookup(#REF!, 'Class Skills'!$A:$BE,MATCH(AE17,'Class Skills'!$1:$1,0),false),"")="X"),"X",) -> X | AE17: Heal | AI17: =HLOOKUP(AE17,'Class Skills'!$1:$3,3,false) -> Wis | AJ17: =if(AND(HLOOKUP(AE17,'Class Skills'!$1:$2,2,false)="Trained Only",AL17<1),,SUM(AL17:AQ17)) -> 0 | AK17: = | AM17: =IFERROR(__xludf.DUMMYFUNCTION("offset($E$8,match(AI17,ARRAYFORMULA(Proper(lower(REGEXEXTRACT($E$9:$E$14,""\w\w\w"")))),0),2)"),0.0) -> 0 | AN17: =if(AND(AL17 > 0,AD17 ="X"), 3, ) | AP17: =IFERROR(__xludf.DUMMYFUNCTION("if( or(arrayformula(regexmatch($AR$76:$AR$110,AE17))), sum(arrayformula(iferror(value(regexextract(filter( $AR$76:$AR$110, $K$76:$K$110=""ACTIVE"", regexmatch($AR$76:$AR$110,AE17)), ""[-\d]+"")))))+tSkill,tSkill)"),0.0) -> 0 | AQ17: =iferror(if( if(hlookup(AE17,'Class Skills'!$1:$4,4,false)="Armor Penalty",'Formula References'!$Q$156,) +if(AND(isnumber($C$38),AE17="Climb"),8,) +if(AND(isnumber($C$39),AE17="Swim"),8,) +if(AE17="Fly", Vlookup(Size,SizeTable,5,False),) +if(AE17="Fly",if($M$37="Clumsy",-8,if($M$37="Poor",-4,if($M$37="Average",0,if($M$37="Good",4,if($M$37="Perfect",8,0)))))) +if(AE17="Stealth",Vlookup(Size,SizeTable,6,False)) =0,, if(hlookup(AE17,'Class Skills'!$1:$4,4,false)="Armor Penalty",'Formula References'!$Q$156,) +if(AND(isnumber($C$38),AE17="Climb"),8,) +if(AND(isnumber($C$39),AE17="Swim"),8,) +if(AE17="Fly", Vlookup(Size,SizeTable,5,False),) +if(AE17="Fly",if($M$37="Clumsy",-8,if($M$37="Poor",-4,if($M$37="Average",0,if($M$37="Good",4,if($M$37="Perfect",8,0)))))) +if(AE17="Stealth",Vlookup(Size,SizeTable,6,False))),"")
